Workbook

Sheet RECHERCHE DELSA
B2: RECHERCHE DELSA
B4: Tapez une reference DELSA (ex. DE 458, DRY 1006, DP 3105) dans la cellule jaune puis Entree. La fiche complete s'affiche avec l'equivalent EKSPER et toutes les autres marques.
B5: RECHERCHE : | C5: DE 458 | Q5: =IF(TRIM($C$5)="","",SUBSTITUTE(UPPER(TRIM($C$5))," ","")) -> DE458
B6: Reference normalisee : | C6: =IF($Q$5="","",$Q$5) -> DE458 | D6: Resultats trouves : | E6: =IF($Q$5="","—",SUMPRODUCT(--ISNUMBER(SEARCH($Q$5,CORRESPONDANCES!$Q$2:$Q$3270)))) -> 1 | Q6: =IF($Q$5="","",IF(ISNUMBER(MATCH("*"&$Q$5&"*",CORRESPONDANCES!$Q$2:$Q$3270,0)),MATCH("*"&$Q$5&"*",CORRESPONDANCES!$Q$2:$Q$3270,0)+1,"")) -> 3
Q7: =IF(OR($Q$5="",$Q$7=""),"",IF(ISNUMBER(MATCH("*"&$Q$5&"*",INDEX(CORRESPONDANCES!$Q:$Q,$Q$7+1):CORRESPONDANCES!$Q$3270,0)),$Q$7+MATCH("*"&$Q$5&"*",INDEX(CORRESPONDANCES!$Q:$Q,$Q$7+1):CORRESPONDANCES!$Q$3270,0),""))
Q8: =IF(OR($Q$5="",$Q$8=""),"",IF(ISNUMBER(MATCH("*"&$Q$5&"*",INDEX(CORRESPONDANCES!$Q:$Q,$Q$8+1):CORRESPONDANCES!$Q$3270,0)),$Q$8+MATCH("*"&$Q$5&"*",INDEX(CORRESPONDANCES!$Q:$Q,$Q$8+1):CORRESPONDANCES!$Q$3270,0),""))
B9: DELSA | C9: =IF($Q$6="","",INDEX(CORRESPONDANCES!B:B,$Q$6)) -> DE 458 E | D9: EKSPER | E9: =IF($Q$6="","",INDEX(CORRESPONDANCES!C:C,$Q$6)) -> ECO014 | Q9: =IF(OR($Q$5="",$Q$9=""),"",IF(ISNUMBER(MATCH("*"&$Q$5&"*",INDEX(CORRESPONDANCES!$Q:$Q,$Q$9+1):CORRESPONDANCES!$Q$3270,0)),$Q$9+MATCH("*"&$Q$5&"*",INDEX(CORRESPONDANCES!$Q:$Q,$Q$9+1):CORRESPONDANCES!$Q$3270,0),""))
B10: MANN | C10: =IF($Q$6="","",INDEX(CORRESPONDANCES!D:D,$Q$6)) -> HU 715/4 x | D10: ASAS | E10: =IF($Q$6="","",INDEX(CORRESPONDANCES!E:E,$Q$6)) -> AS 1534 | Q10: =IF(OR($Q$5="",$Q$10=""),"",IF(ISNUMBER(MATCH("*"&$Q$5&"*",INDEX(CORRESPONDANCES!$Q:$Q,$Q$10+1):CORRESPONDANCES!$Q$3270,0)),$Q$10+MATCH("*"&$Q$5&"*",INDEX(CORRESPONDANCES!$Q:$Q,$Q$10+1):CORRESPONDANCES!$Q$3270,0),""))
B11: FIL | C11: =IF($Q$6="","",INDEX(CORRESPONDANCES!F:F,$Q$6)) -> MLE 1375 | D11: MISFAT | E11: =IF($Q$6="","",INDEX(CORRESPONDANCES!G:G,$Q$6))
B12: MAHLE | C12: =IF($Q$6="","",INDEX(CORRESPONDANCES!H:H,$Q$6)) | D12: FLEETGUARD | E12: =IF($Q$6="","",INDEX(CORRESPONDANCES!I:I,$Q$6))
B13: HENGST | C13: =IF($Q$6="","",INDEX(CORRESPONDANCES!J:J,$Q$6)) -> E104HD43 | D13: AUTRES | E13: =IF($Q$6="","",INDEX(CORRESPONDANCES!K:K,$Q$6))
B14: OEM | C14: =IF($Q$6="","",INDEX(CORRESPONDANCES!O:O,$Q$6)) -> 11421432097
B15: MARQUE/VEHICULE | C15: =IF($Q$6="","",INDEX(CORRESPONDANCES!M:M,$Q$6)) -> BMW
B16: TYPE FILTRE | C16: =IF($Q$6="","",INDEX(CORRESPONDANCES!N:N,$Q$6)) -> OIL FILTERS
B17: APPLICATION
B18: =IF($Q$6="","",INDEX(CORRESPONDANCES!$L:$L,$Q$6)) -> E-36 3.16i, 3.18, 3.18i,3.18is, 3.18ti Compact M-43
B20: AUTRES CORRESPONDANCES TROUVEES (si plusieurs fiches correspondent)
A21: N° | B21: DELSA | C21: EKSPER | D21: MANN
A22: 1 | B22: =IF($Q$7="","",INDEX(CORRESPONDANCES!B:B,$Q$7)) | C22: =IF($Q$7="","",INDEX(CORRESPONDANCES!C:C,$Q$7)) | D22: =IF($Q$7="","",INDEX(CORRESPONDANCES!D:D,$Q$7)) | E22: =IF($Q$7="","",INDEX(CORRESPONDANCES!L:L,$Q$7))
A23: 2 | B23: =IF($Q$8="","",INDEX(CORRESPONDANCES!B:B,$Q$8)) | C23: =IF($Q$8="","",INDEX(CORRESPONDANCES!C:C,$Q$8)) | D23: =IF($Q$8="","",INDEX(CORRESPONDANCES!D:D,$Q$8)) | E23: =IF($Q$8="","",INDEX(CORRESPONDANCES!L:L,$Q$8))
A24: 3 | B24: =IF($Q$9="","",INDEX(CORRESPONDANCES!B:B,$Q$9)) | C24: =IF($Q$9="","",INDEX(CORRESPONDANCES!C:C,$Q$9)) | D24: =IF($Q$9="","",INDEX(CORRESPONDANCES!D:D,$Q$9)) | E24: =IF($Q$9="","",INDEX(CORRESPONDANCES!L:L,$Q$9))
A25: 4 | B25: =IF($Q$10="","",INDEX(CORRESPONDANCES!B:B,$Q$10)) | C25: =IF($Q$10="","",INDEX(CORRESPONDANCES!C:C,$Q$10)) | D25: =IF($Q$10="","",INDEX(CORRESPONDANCES!D:D,$Q$10)) | E25: =IF($Q$10="","",INDEX(CORRESPONDANCES!L:L,$Q$10))
B27: Si les resultats ne changent pas quand vous tapez : cliquez sur ACTIVER LA MODIFICATION (barre jaune en haut), puis tapez votre reference dans la cellule jaune et appuyez sur Entree.

Sheet RECHERCHE EKSPER
B2: RECHERCHE EKSPER
B4: Tapez une reference EKSPER (ex. ECO049, ESD001, EO060) dans la cellule jaune puis Entree. La fiche complete s'affiche avec l'equivalent DELSA et toutes les autres marques.
B5: RECHERCHE : | C5: ECO049 | Q5: =IF(TRIM($C$5)="","",SUBSTITUTE(UPPER(TRIM($C$5))," ","")) -> ECO049
B6: Reference normalisee : | C6: =IF($Q$5="","",$Q$5) -> ECO049 | D6: Resultats trouves : | E6: =IF($Q$5="","—",SUMPRODUCT(--ISNUMBER(SEARCH($Q$5,CORRESPONDANCES!$R$2:$R$3270)))) -> 1 | Q6: =IF($Q$5="","",IF(ISNUMBER(MATCH("*"&$Q$5&"*",CORRESPONDANCES!$R$2:$R$3270,0)),MATCH("*"&$Q$5&"*",CORRESPONDANCES!$R$2:$R$3270,0)+1,"")) -> 6
Q7: =IF(OR($Q$5="",$Q$7=""),"",IF(ISNUMBER(MATCH("*"&$Q$5&"*",INDEX(CORRESPONDANCES!$R:$R,$Q$7+1):CORRESPONDANCES!$R$3270,0)),$Q$7+MATCH("*"&$Q$5&"*",INDEX(CORRESPONDANCES!$R:$R,$Q$7+1):CORRESPONDANCES!$R$3270,0),""))
Q8: =IF(OR($Q$5="",$Q$8=""),"",IF(ISNUMBER(MATCH("*"&$Q$5&"*",INDEX(CORRESPONDANCES!$R:$R,$Q$8+1):CORRESPONDANCES!$R$3270,0)),$Q$8+MATCH("*"&$Q$5&"*",INDEX(CORRESPONDANCES!$R:$R,$Q$8+1):CORRESPONDANCES!$R$3270,0),""))
B9: DELSA | C9: =IF($Q$6="","",INDEX(CORRESPONDANCES!B:B,$Q$6)) -> DE 473 E | D9: EKSPER | E9: =IF($Q$6="","",INDEX(CORRESPONDANCES!C:C,$Q$6)) -> ECO049 | Q9: =IF(OR($Q$5="",$Q$9=""),"",IF(ISNUMBER(MATCH("*"&$Q$5&"*",INDEX(CORRESPONDANCES!$R:$R,$Q$9+1):CORRESPONDANCES!$R$3270,0)),$Q$9+MATCH("*"&$Q$5&"*",INDEX(CORRESPONDANCES!$R:$R,$Q$9+1):CORRESPONDANCES!$R$3270,0),""))
B10: MANN | C10: =IF($Q$6="","",INDEX(CORRESPONDANCES!D:D,$Q$6)) -> HU 722 x | D10: ASAS | E10: =IF($Q$6="","",INDEX(CORRESPONDANCES!E:E,$Q$6)) -> AS 1572 | Q10: =IF(OR($Q$5="",$Q$10=""),"",IF(ISNUMBER(MATCH("*"&$Q$5&"*",INDEX(CORRESPONDANCES!$R:$R,$Q$10+1):CORRESPONDANCES!$R$3270,0)),$Q$10+MATCH("*"&$Q$5&"*",INDEX(CORRESPONDANCES!$R:$R,$Q$10+1):CORRESPONDANCES!$R$3270,0),""))
B11: FIL | C11: =IF($Q$6="","",INDEX(CORRESPONDANCES!F:F,$Q$6)) -> MLE 1448A | D11: MISFAT | E11: =IF($Q$6="","",INDEX(CORRESPONDANCES!G:G,$Q$6)) -> L021
B12: MAHLE | C12: =IF($Q$6="","",INDEX(CORRESPONDANCES!H:H,$Q$6)) -> OX368D | D12: FLEETGUARD | E12: =IF($Q$6="","",INDEX(CORRESPONDANCES!I:I,$Q$6))
B13: HENGST | C13: =IF($Q$6="","",INDEX(CORRESPONDANCES!J:J,$Q$6)) | D13: AUTRES | E13: =IF($Q$6="","",INDEX(CORRESPONDANCES!K:K,$Q$6))
B14: OEM | C14: =IF($Q$6="","",INDEX(CORRESPONDANCES!O:O,$Q$6)) -> 11427787697
B15: MARQUE/VEHICULE | C15: =IF($Q$6="","",INDEX(CORRESPONDANCES!M:M,$Q$6)) -> BMW
B16: TYPE FILTRE | C16: =IF($Q$6="","",INDEX(CORRESPONDANCES!N:N,$Q$6)) -> OIL FILTERS
B17: APPLICATION
B18: =IF($Q$6="","",INDEX(CORRESPONDANCES!$L:$L,$Q$6)) -> E-46 320d, 320td Compact (08/01=>) M-47
B20: AUTRES CORRESPONDANCES TROUVEES (si plusieurs fiches correspondent)
A21: N° | B21: DELSA | C21: EKSPER | D21: MANN
A22: 1 | B22: =IF($Q$7="","",INDEX(CORRESPONDANCES!B:B,$Q$7)) | C22: =IF($Q$7="","",INDEX(CORRESPONDANCES!C:C,$Q$7)) | D22: =IF($Q$7="","",INDEX(CORRESPONDANCES!D:D,$Q$7)) | E22: =IF($Q$7="","",INDEX(CORRESPONDANCES!L:L,$Q$7))
A23: 2 | B23: =IF($Q$8="","",INDEX(CORRESPONDANCES!B:B,$Q$8)) | C23: =IF($Q$8="","",INDEX(CORRESPONDANCES!C:C,$Q$8)) | D23: =IF($Q$8="","",INDEX(CORRESPONDANCES!D:D,$Q$8)) | E23: =IF($Q$8="","",INDEX(CORRESPONDANCES!L:L,$Q$8))
A24: 3 | B24: =IF($Q$9="","",INDEX(CORRESPONDANCES!B:B,$Q$9)) | C24: =IF($Q$9="","",INDEX(CORRESPONDANCES!C:C,$Q$9)) | D24: =IF($Q$9="","",INDEX(CORRESPONDANCES!D:D,$Q$9)) | E24: =IF($Q$9="","",INDEX(CORRESPONDANCES!L:L,$Q$9))
A25: 4 | B25: =IF($Q$10="","",INDEX(CORRESPONDANCES!B:B,$Q$10)) | C25: =IF($Q$10="","",INDEX(CORRESPONDANCES!C:C,$Q$10)) | D25: =IF($Q$10="","",INDEX(CORRESPONDANCES!D:D,$Q$10)) | E25: =IF($Q$10="","",INDEX(CORRESPONDANCES!L:L,$Q$10))
B27: Si les resultats ne changent pas quand vous tapez : cliquez sur ACTIVER LA MODIFICATION (barre jaune en haut), puis tapez votre reference dans la cellule jaune et appuyez sur Entree.

Sheet RECHERCHE AUTRES
B2: RECHERCHE AUTRES
B4: Tapez une reference d'une autre marque (MANN, ASAS, FIL, MISFAT, MAHLE, FLEETGUARD, HENGST ou un numero OEM) — majuscules ou minuscules, avec ou sans espaces. La fiche complete s'affiche avec le couple DELSA / EKSPER.
B5: RECHERCHE : | C5: HU 722 x | Q5: =IF(TRIM($C$5)="","",SUBSTITUTE(UPPER(TRIM($C$5))," ","")) -> HU722X
B6: Reference normalisee : | C6: =IF($Q$5="","",$Q$5) -> HU722X | D6: Resultats trouves : | E6: =IF($Q$5="","—",SUMPRODUCT(--ISNUMBER(SEARCH($Q$5,CORRESPONDANCES!$A$2:$A$3270)))) -> 1 | Q6: =IF($Q$5="","",IF(ISNUMBER(MATCH("*"&$Q$5&"*",CORRESPONDANCES!$A$2:$A$3270,0)),MATCH("*"&$Q$5&"*",CORRESPONDANCES!$A$2:$A$3270,0)+1,"")) -> 6
Q7: =IF(OR($Q$5="",$Q$7=""),"",IF(ISNUMBER(MATCH("*"&$Q$5&"*",INDEX(CORRESPONDANCES!$A:$A,$Q$7+1):CORRESPONDANCES!$A$3270,0)),$Q$7+MATCH("*"&$Q$5&"*",INDEX(CORRESPONDANCES!$A:$A,$Q$7+1):CORRESPONDANCES!$A$3270,0),""))
Q8: =IF(OR($Q$5="",$Q$8=""),"",IF(ISNUMBER(MATCH("*"&$Q$5&"*",INDEX(CORRESPONDANCES!$A:$A,$Q$8+1):CORRESPONDANCES!$A$3270,0)),$Q$8+MATCH("*"&$Q$5&"*",INDEX(CORRESPONDANCES!$A:$A,$Q$8+1):CORRESPONDANCES!$A$3270,0),""))
B9: DELSA | C9: =IF($Q$6="","",INDEX(CORRESPONDANCES!B:B,$Q$6)) -> DE 473 E | D9: EKSPER | E9: =IF($Q$6="","",INDEX(CORRESPONDANCES!C:C,$Q$6)) -> ECO049 | Q9: =IF(OR($Q$5="",$Q$9=""),"",IF(ISNUMBER(MATCH("*"&$Q$5&"*",INDEX(CORRESPONDANCES!$A:$A,$Q$9+1):CORRESPONDANCES!$A$3270,0)),$Q$9+MATCH("*"&$Q$5&"*",INDEX(CORRESPONDANCES!$A:$A,$Q$9+1):CORRESPONDANCES!$A$3270,0),""))
B10: MANN | C10: =IF($Q$6="","",INDEX(CORRESPONDANCES!D:D,$Q$6)) -> HU 722 x | D10: ASAS | E10: =IF($Q$6="","",INDEX(CORRESPONDANCES!E:E,$Q$6)) -> AS 1572 | Q10: =IF(OR($Q$5="",$Q$10=""),"",IF(ISNUMBER(MATCH("*"&$Q$5&"*",INDEX(CORRESPONDANCES!$A:$A,$Q$10+1):CORRESPONDANCES!$A$3270,0)),$Q$10+MATCH("*"&$Q$5&"*",INDEX(CORRESPONDANCES!$A:$A,$Q$10+1):CORRESPONDANCES!$A$3270,0),""))
B11: FIL | C11: =IF($Q$6="","",INDEX(CORRESPONDANCES!F:F,$Q$6)) -> MLE 1448A | D11: MISFAT | E11: =IF($Q$6="","",INDEX(CORRESPONDANCES!G:G,$Q$6)) -> L021
B12: MAHLE | C12: =IF($Q$6="","",INDEX(CORRESPONDANCES!H:H,$Q$6)) -> OX368D | D12: FLEETGUARD | E12: =IF($Q$6="","",INDEX(CORRESPONDANCES!I:I,$Q$6))
B13: HENGST | C13: =IF($Q$6="","",INDEX(CORRESPONDANCES!J:J,$Q$6)) | D13: AUTRES | E13: =IF($Q$6="","",INDEX(CORRESPONDANCES!K:K,$Q$6))
B14: OEM | C14: =IF($Q$6="","",INDEX(CORRESPONDANCES!O:O,$Q$6)) -> 11427787697
B15: MARQUE/VEHICULE | C15: =IF($Q$6="","",INDEX(CORRESPONDANCES!M:M,$Q$6)) -> BMW
B16: TYPE FILTRE | C16: =IF($Q$6="","",INDEX(CORRESPONDANCES!N:N,$Q$6)) -> OIL FILTERS
B17: APPLICATION
B18: =IF($Q$6="","",INDEX(CORRESPONDANCES!$L:$L,$Q$6)) -> E-46 320d, 320td Compact (08/01=>) M-47
B20: AUTRES CORRESPONDANCES TROUVEES (si plusieurs fiches correspondent)
A21: N° | B21: DELSA | C21: EKSPER | D21: MANN
A22: 1 | B22: =IF($Q$7="","",INDEX(CORRESPONDANCES!B:B,$Q$7)) | C22: =IF($Q$7="","",INDEX(CORRESPONDANCES!C:C,$Q$7)) | D22: =IF($Q$7="","",INDEX(CORRESPONDANCES!D:D,$Q$7)) | E22: =IF($Q$7="","",INDEX(CORRESPONDANCES!L:L,$Q$7))
A23: 2 | B23: =IF($Q$8="","",INDEX(CORRESPONDANCES!B:B,$Q$8)) | C23: =IF($Q$8="","",INDEX(CORRESPONDANCES!C:C,$Q$8)) | D23: =IF($Q$8="","",INDEX(CORRESPONDANCES!D:D,$Q$8)) | E23: =IF($Q$8="","",INDEX(CORRESPONDANCES!L:L,$Q$8))
A24: 3 | B24: =IF($Q$9="","",INDEX(CORRESPONDANCES!B:B,$Q$9)) | C24: =IF($Q$9="","",INDEX(CORRESPONDANCES!C:C,$Q$9)) | D24: =IF($Q$9="","",INDEX(CORRESPONDANCES!D:D,$Q$9)) | E24: =IF($Q$9="","",INDEX(CORRESPONDANCES!L:L,$Q$9))
A25: 4 | B25: =IF($Q$10="","",INDEX(CORRESPONDANCES!B:B,$Q$10)) | C25: =IF($Q$10="","",INDEX(CORRESPONDANCES!C:C,$Q$10)) | D25: =IF($Q$10="","",INDEX(CORRESPONDANCES!D:D,$Q$10)) | E25: =IF($Q$10="","",INDEX(CORRESPONDANCES!L:L,$Q$10))
B27: Si les resultats ne changent pas quand vous tapez : cliquez sur ACTIVER LA MODIFICATION (barre jaune en haut), puis tapez votre reference dans la cellule jaune et appuyez sur Entree.

Sheet TOUTES LES REFERENCES
A1: REFERENCE | B1: REF SANS ESPACES | C1: MARQUE | D1: DELSA | E1: EKSPER | F1: MANN | G1: ASAS | H1: FIL | I1: MISFAT | J1: MAHLE | K1: FLEETGUARD | L1: HENGST | M1: AUTRES | N1: APPLICATION | O1: MARQUE/VEHICULE | P1: TYPE FILTRE | Q1: OEM
A2: DE 341 | B2: DE341 | C2: DELSA | D2: DE 341 | E2: EO060 | F2: H 973 x | G2: AS 276 x | H2: ML 1323 | N2: E-34 524 td ( 88<=>95) M-21 | O2: BMW | P2: OIL FILTERS | Q2: 11429064276
A3: EO060 | B3: EO060 | C3: EKSPER | D3: DE 341 | E3: EO060 | F3: H 973 x | G3: AS 276 x | H3: ML 1323 | N3: E-34 524 td ( 88<=>95) M-21 | O3: BMW | P3: OIL FILTERS | Q3: 11429064276
A4: H 973 x | B4: H973X | C4: MANN | D4: DE 341 | E4: EO060 | F4: H 973 x | G4: AS 276 x | H4: ML 1323 | N4: E-34 524 td ( 88<=>95) M-21 | O4: BMW | P4: OIL FILTERS | Q4: 11429064276
A5: AS 276 x | B5: AS276X | C5: ASAS | D5: DE 341 | E5: EO060 | F5: H 973 x | G5: AS 276 x | H5: ML 1323 | N5: E-34 524 td ( 88<=>95) M-21 | O5: BMW | P5: OIL FILTERS | Q5: 11429064276
A6: ML 1323 | B6: ML1323 | C6: FIL | D6: DE 341 | E6: EO060 | F6: H 973 x | G6: AS 276 x | H6: ML 1323 | N6: E-34 524 td ( 88<=>95) M-21 | O6: BMW | P6: OIL FILTERS | Q6: 11429064276
A7: 11429064276 | B7: 11429064276 | C7: OEM | D7: DE 341 | E7: EO060 | F7: H 973 x | G7: AS 276 x | H7: ML 1323 | N7: E-34 524 td ( 88<=>95) M-21 | O7: BMW | P7: OIL FILTERS | Q7: 11429064276
A8: DE 458 E | B8: DE458E | C8: DELSA | D8: DE 458 E | E8: ECO014 | F8: HU 715/4 x | G8: AS 1534 | H8: MLE 1375 | L8: E104HD43 | N8: E-36 3.16i, 3.18, 3.18i,3.18is, 3.18ti Compact M-43 | O8: BMW | P8: OIL FILTERS | Q8: 11421432097
A9: ECO014 | B9: ECO014 | C9: EKSPER | D9: DE 458 E | E9: ECO014 | F9: HU 715/4 x | G9: AS 1534 | H9: MLE 1375 | L9: E104HD43 | N9: E-36 3.16i, 3.18, 3.18i,3.18is, 3.18ti Compact M-43 | O9: BMW | P9: OIL FILTERS | Q9: 11421432097
A10: HU 715/4 x | B10: HU715/4X | C10: MANN | D10: DE 458 E | E10: ECO014 | F10: HU 715/4 x | G10: AS 1534 | H10: MLE 1375 | L10: E104HD43 | N10: E-36 3.16i, 3.18, 3.18i,3.18is, 3.18ti Compact M-43 | O10: BMW | P10: OIL FILTERS | Q10: 11421432097
A11: AS 1534 | B11: AS1534 | C11: ASAS | D11: DE 458 E | E11: ECO014 | F11: HU 715/4 x | G11: AS 1534 | H11: MLE 1375 | L11: E104HD43 | N11: E-36 3.16i, 3.18, 3.18i,3.18is, 3.18ti Compact M-43 | O11: BMW | P11: OIL FILTERS | Q11: 11421432097
A12: MLE 1375 | B12: MLE1375 | C12: FIL | D12: DE 458 E | E12: ECO014 | F12: HU 715/4 x | G12: AS 1534 | H12: MLE 1375 | L12: E104HD43 | N12: E-36 3.16i, 3.18, 3.18i,3.18is, 3.18ti Compact M-43 | O12: BMW | P12: OIL FILTERS | Q12: 11421432097
A13: E104HD43 | B13: E104HD43 | C13: HENGST | D13: DE 458 E | E13: ECO014 | F13: HU 715/4 x | G13: AS 1534 | H13: MLE 1375 | L13: E104HD43 | N13: E-36 3.16i, 3.18, 3.18i,3.18is, 3.18ti Compact M-43 | O13: BMW | P13: OIL FILTERS | Q13: 11421432097
A14: 11421432097 | B14: 11421432097 | C14: OEM | D14: DE 458 E | E14: ECO014 | F14: HU 715/4 x | G14: AS 1534 | H14: MLE 1375 | L14: E104HD43 | N14: E-36 3.16i, 3.18, 3.18i,3.18is, 3.18ti Compact M-43 | O14: BMW | P14: OIL FILTERS | Q14: 11421432097
A15: DE 463 E | B15: DE463E | C15: DELSA | D15: DE 463 E | E15: ECO007Z | F15: HU 718/1 z | G15: AS 1548 | H15: MLE 1353B | N15: E-46 320d, 320TD,Compact (08/01=>) M-47 | O15: BMW | P15: OIL FILTERS | Q15: 11422247018
A16: ECO007Z | B16: ECO007Z | C16: EKSPER | D16: DE 463 E | E16: ECO007Z | F16: HU 718/1 z | G16: AS 1548 | H16: MLE 1353B | N16: E-46 320d, 320TD,Compact (08/01=>) M-47 | O16: BMW | P16: OIL FILTERS | Q16: 11422247018
A17: HU 718/1 z | B17: HU718/1Z | C17: MANN | D17: DE 463 E | E17: ECO007Z | F17: HU 718/1 z | G17: AS 1548 | H17: MLE 1353B | N17: E-46 320d, 320TD,Compact (08/01=>) M-47 | O17: BMW | P17: OIL FILTERS | Q17: 11422247018
A18: AS 1548 | B18: AS1548 | C18: ASAS | D18: DE 463 E | E18: ECO007Z | F18: HU 718/1 z | G18: AS 1548 | H18: MLE 1353B | N18: E-46 320d, 320TD,Compact (08/01=>) M-47 | O18: BMW | P18: OIL FILTERS | Q18: 11422247018
A19: MLE 1353B | B19: MLE1353B | C19: FIL | D19: DE 463 E | E19: ECO007Z | F19: HU 718/1 z | G19: AS 1548 | H19: MLE 1353B | N19: E-46 320d, 320TD,Compact (08/01=>) M-47 | O19: BMW | P19: OIL FILTERS | Q19: 11422247018
A20: 11422247018 | B20: 11422247018 | C20: OEM | D20: DE 463 E | E20: ECO007Z | F20: HU 718/1 z | G20: AS 1548 | H20: MLE 1353B | N20: E-46 320d, 320TD,Compact (08/01=>) M-47 | O20: BMW | P20: OIL FILTERS | Q20: 11422247018
A21: DE 472 E | B21: DE472E | C21: DELSA | D21: DE 472 E | E21: ECO060 | F21: HU 721/4 x | G21: AS 2504 | H21: MLE 1478 | N21: E-46 330d, X5(E53) 3.0d (03-06) M-57 | O21: BMW | P21: OIL FILTERS | Q21: 11427788454
A22: ECO060 | B22: ECO060 | C22: EKSPER | D22: DE 472 E | E22: ECO060 | F22: HU 721/4 x | G22: AS 2504 | H22: MLE 1478 | N22: E-46 330d, X5(E53) 3.0d (03-06) M-57 | O22: BMW | P22: OIL FILTERS | Q22: 11427788454
A23: HU 721/4 x | B23: HU721/4X | C23: MANN | D23: DE 472 E | E23: ECO060 | F23: HU 721/4 x | G23: AS 2504 | H23: MLE 1478 | N23: E-46 330d, X5(E53) 3.0d (03-06) M-57 | O23: BMW | P23: OIL FILTERS | Q23: 11427788454
A24: AS 2504 | B24: AS2504 | C24: ASAS | D24: DE 472 E | E24: ECO060 | F24: HU 721/4 x | G24: AS 2504 | H24: MLE 1478 | N24: E-46 330d, X5(E53) 3.0d (03-06) M-57 | O24: BMW | P24: OIL FILTERS | Q24: 11427788454
A25: MLE 1478 | B25: MLE1478 | C25: FIL | D25: DE 472 E | E25: ECO060 | F25: HU 721/4 x | G25: AS 2504 | H25: MLE 1478 | N25: E-46 330d, X5(E53) 3.0d (03-06) M-57 | O25: BMW | P25: OIL FILTERS | Q25: 11427788454
A26: 11427788454 | B26: 11427788454 | C26: OEM | D26: DE 472 E | E26: ECO060 | F26: HU 721/4 x | G26: AS 2504 | H26: MLE 1478 | N26: E-46 330d, X5(E53) 3.0d (03-06) M-57 | O26: BMW | P26: OIL FILTERS | Q26: 11427788454
A27: DE 473 E | B27: DE473E | C27: DELSA | D27: DE 473 E | E27: ECO049 | F27: HU 722 x | G27: AS 1572 | H27: MLE 1448A | I27: L021 | J27: OX368D | N27: E-46 320d, 320td Compact (08/01=>) M-47 | O27: BMW | P27: OIL FILTERS | Q27: 11427787697
A28: ECO049 | B28: ECO049 | C28: EKSPER | D28: DE 473 E | E28: ECO049 | F28: HU 722 x | G28: AS 1572 | H28: MLE 1448A | I28: L021 | J28: OX368D | N28: E-46 320d, 320td Compact (08/01=>) M-47 | O28: BMW | P28: OIL FILTERS | Q28: 11427787697
A29: HU 722 x | B29: HU722X | C29: MANN | D29: DE 473 E | E29: ECO049 | F29: HU 722 x | G29: AS 1572 | H29: MLE 1448A | I29: L021 | J29: OX368D | N29: E-46 320d, 320td Compact (08/01=>) M-47 | O29: BMW | P29: OIL FILTERS | Q29: 11427787697
A30: AS 1572 | B30: AS1572 | C30: ASAS | D30: DE 473 E | E30: ECO049 | F30: HU 722 x | G30: AS 1572 | H30: MLE 1448A | I30: L021 | J30: OX368D | N30: E-46 320d, 320td Compact (08/01=>) M-47 | O30: BMW | P30: OIL FILTERS | Q30: 11427787697
A31: MLE 1448A | B31: MLE1448A | C31: FIL | D31: DE 473 E | E31: ECO049 | F31: HU 722 x | G31: AS 1572 | H31: MLE 1448A | I31: L021 | J31: OX368D | N31: E-46 320d, 320td Compact (08/01=>) M-47 | O31: BMW | P31: OIL FILTERS | Q31: 11427787697
A32: L021 | B32: L021 | C32: MISFAT | D32: DE 473 E | E32: ECO049 | F32: HU 722 x | G32: AS 1572 | H32: MLE 1448A | I32: L021 | J32: OX368D | N32: E-46 320d, 320td Compact (08/01=>) M-47 | O32: BMW | P32: OIL FILTERS | Q32: 11427787697
A33: OX368D | B33: OX368D | C33: MAHLE | D33: DE 473 E | E33: ECO049 | F33: HU 722 x | G33: AS 1572 | H33: MLE 1448A | I33: L021 | J33: OX368D | N33: E-46 320d, 320td Compact (08/01=>) M-47 | O33: BMW | P33: OIL FILTERS | Q33: 11427787697
A34: 11427787697 | B34: 11427787697 | C34: OEM | D34: DE 473 E | E34: ECO049 | F34: HU 722 x | G34: AS 1572 | H34: MLE 1448A | I34: L021 | J34: OX368D | N34: E-46 320d, 320td Compact (08/01=>) M-47 | O34: BMW | P34: OIL FILTERS | Q34: 11427787697
A35: DE 490 E | B35: DE490E | C35: DELSA | D35: DE 490 E | E35: ECO009 | F35: HU 925/4 x | G35: AS 1555 | H35: MLE 1376 | I35: 0 | J35: OX1541D | L35: E106HD34 | N35: E-39, E-46 M-52 | O35: BMW | P35: OIL FILTERS | Q35: 11421427908
A36: ECO009 | B36: ECO009 | C36: EKSPER | D36: DE 490 E | E36: ECO009 | F36: HU 925/4 x | G36: AS 1555 | H36: MLE 1376 | I36: 0 | J36: OX1541D | L36: E106HD34 | N36: E-39, E-46 M-52 | O36: BMW | P36: OIL FILTERS | Q36: 11421427908
A37: HU 925/4 x | B37: HU925/4X | C37: MANN | D37: DE 490 E | E37: ECO009 | F37: HU 925/4 x | G37: AS 1555 | H37: MLE 1376 | I37: 0 | J37: OX1541D | L37: E106HD34 | N37: E-39, E-46 M-52 | O37: BMW | P37: OIL FILTERS | Q37: 11421427908
A38: AS 1555 | B38: AS1555 | C38: ASAS | D38: DE 490 E | E38: ECO009 | F38: HU 925/4 x | G38: AS 1555 | H38: MLE 1376 | I38: 0 | J38: OX1541D | L38: E106HD34 | N38: E-39, E-46 M-52 | O38: BMW | P38: OIL FILTERS | Q38: 11421427908
A39: MLE 1376 | B39: MLE1376 | C39: FIL | D39: DE 490 E | E39: ECO009 | F39: HU 925/4 x | G39: AS 1555 | H39: MLE 1376 | I39: 0 | J39: OX1541D | L39: E106HD34 | N39: E-39, E-46 M-52 | O39: BMW | P39: OIL FILTERS | Q39: 11421427908
A40: 0 | B40: 0 | C40: MISFAT | D40: DE 490 E | E40: ECO009 | F40: HU 925/4 x | G40: AS 1555 | H40: MLE 1376 | I40: 0 | J40: OX1541D | L40: E106HD34 | N40: E-39, E-46 M-52 | O40: BMW | P40: OIL FILTERS | Q40: 11421427908
...

Sheet CORRESPONDANCES
A1: TOUTES LES REFS SANS ESPACES (colonne de recherche) | B1: DELSA | C1: EKSPER | D1: MANN | E1: ASAS | F1: FIL | G1: MISFAT | H1: MAHLE | I1: FLEETGUARD | J1: HENGST | K1: AUTRES | L1: APPLICATION | M1: MARQUE/VEHICULE | N1: TYPE FILTRE | O1: OEM | P1: SOURCE
A2: DE341 EO060 H973X AS276X ML1323 11429064276 | B2: DE 341 | C2: EO060 | D2: H 973 x | E2: AS 276 x | F2: ML 1323 | L2: E-34 524 td ( 88<=>95) M-21 | M2: BMW | N2: OIL FILTERS | O2: 11429064276 | P2: MATCH | Q2: DE341 | R2: EO060
A3: DE458E ECO014 HU715/4X AS1534 MLE1375 E104HD43 11421432097 | B3: DE 458 E | C3: ECO014 | D3: HU 715/4 x | E3: AS 1534 | F3: MLE 1375 | J3: E104HD43 | L3: E-36 3.16i, 3.18, 3.18i,3.18is, 3.18ti Compact M-43 | M3: BMW | N3: OIL FILTERS | O3: 11421432097 | P3: MATCH | Q3: DE458E | R3: ECO014
A4: DE463E ECO007Z HU718/1Z AS1548 MLE1353B 11422247018 | B4: DE 463 E | C4: ECO007Z | D4: HU 718/1 z | E4: AS 1548 | F4: MLE 1353B | L4: E-46 320d, 320TD,Compact (08/01=>) M-47 | M4: BMW | N4: OIL FILTERS | O4: 11422247018 | P4: MATCH | Q4: DE463E | R4: ECO007Z
A5: DE472E ECO060 HU721/4X AS2504 MLE1478 11427788454 | B5: DE 472 E | C5: ECO060 | D5: HU 721/4 x | E5: AS 2504 | F5: MLE 1478 | L5: E-46 330d, X5(E53) 3.0d (03-06) M-57 | M5: BMW | N5: OIL FILTERS | O5: 11427788454 | P5: MATCH | Q5: DE472E | R5: ECO060
A6: DE473E ECO049 HU722X AS1572 MLE1448A L021 OX368D 11427787697 | B6: DE 473 E | C6: ECO049 | D6: HU 722 x | E6: AS 1572 | F6: MLE 1448A | G6: L021 | H6: OX368D | L6: E-46 320d, 320td Compact (08/01=>) M-47 | M6: BMW | N6: OIL FILTERS | O6: 11427787697 | P6: MATCH | Q6: DE473E | R6: ECO049
A7: DE490E ECO009 HU925/4X AS1555 MLE1376 OX1541D E106HD34 11421427908 | B7: DE 490 E | C7: ECO009 | D7: HU 925/4 x | E7: AS 1555 | F7: MLE 1376 | G7: 0 | H7: OX1541D | J7: E106HD34 | L7: E-39, E-46 M-52 | M7: BMW | N7: OIL FILTERS | O7: 11421427908 | P7: MATCH | Q7: DE490E | R7: ECO009
A8: DE491E ECO021 HU926/3X AS1526 MLE1373A OX68D E110HD24 11421730389 | B8: DE 491 E | C8: ECO021 | D8: HU 926/3 x | E8: AS 1526 | F8: MLE 1373A | G8: 0 | H8: OX68D | J8: E110HD24 | L8: E-34, E-36 M-50 | M8: BMW | N8: OIL FILTERS | O8: 11421730389 | P8: MATCH | Q8: DE491E | R8: ECO021
A9: DE492E ECO022 HU930/3X AS1530 MLE1373B OX41D E128HD24 11429063138 | B9: DE 492 E | C9: ECO022 | D9: HU 930/3 x | E9: AS 1530 | F9: MLE 1373B | G9: 0 | H9: OX41D | J9: E128HD24 | L9: E-34, E-12, E-28, E-23, E-32,M-60 | M9: BMW | N9: OIL FILTERS | O9: 11429063138 | P9: MATCH | Q9: DE492E | R9: ECO022
A10: DS1217 ESO169 W712/6 SP402B ZP507A OC25 LF3338 H90W04 11421258039 | B10: DS 1217 | C10: ESO169 | D10: W 712/6 | E10: SP 402 B | F10: ZP 507A | H10: OC25 | I10: LF3338 | J10: H90W04 | L10: E-21 M-10 | M10: BMW | N10: OIL FILTERS | O10: 11421258039 | P10: MATCH | Q10: DS1217 | R10: ESO169
A11: DS1240 ESO160 W719/5 SP402/ABV ZP523A2 11421266773 | B11: DS 1240 | C11: ESO160 | D11: W 719/5 | E11: SP 402/A BV | F11: ZP 523A2 | L11: E-30 M-20 | M11: BMW | N11: OIL FILTERS | O11: 11421266773 | P11: MATCH | Q11: DS1240 | R11: ESO160
A12: DS1240 ESO192 W719/5 SP402/ABV ZP523A2 11421266773 | B12: DS 1240 | C12: ESO192 | D12: W 719/5 | E12: SP 402/A BV | F12: ZP 523A2 | L12: E-30 M-20 | M12: BMW | N12: OIL FILTERS | O12: 11421266773 | P12: MATCH | Q12: DS1240 | R12: ESO192
A13: DE526FE ECF040 PU742 AS3560 MFE1396 F005 KX69 13322246881 | B13: DE 526 FE | C13: ECF040 | D13: PU 742 | E13: AS3560 | F13: MFE 1396 | G13: F005 | H13: KX69 | L13: E-46 318 d/td, 320 d(Turbodiesel) M-47 | M13: BMW | N13: FUEL FILTERS | O13: 13322246881 | P13: MATCH | Q13: DE526FE | R13: ECF040
A14: DF4124S EPA052 C2567 HF8224F HP2251 LX1617 E616L 1444W91444X3-1147681 13717806046 | B14: DF 4124 S | C14: EPA052 | D14: C 2567 | E14: HF8224F | F14: HP 2251 | H14: LX1617 | J14: E616L | K14: 1444W91444X3-1147681 | L14: Mini Cooper II 1.6 Diesel | M14: BMW | N14: AIR FILTERS | O14: 13717806046 | P14: MATCH | Q14: DF4124S | R14: EPA052
A15: DF4036 EPA027 C26110/1 HF8022 HP2023 LX105 E41L 6040940104 13721715880 | B15: DF 4036 | C15: EPA027 | D15: C 26110/1 | E15: HF 8022 | F15: HP 2023 | H15: LX105 | J15: E41L | K15: 6040940104 | L15: E-30 316i, 318i, E-36 316i, 318iE-34 518i (M-40) | M15: BMW | N15: AIR FILTERS | O15: 13721715880 | P15: MATCH | Q15: DF4036 | R15: EPA027
A16: DE427E ECO030 HU713/1X AS1523 MLE1424 OX371D E60HD110 PURFLUXL330-FIAT73500049-FIAAMFA5677ECO 73500049 | B16: DE 427 E | C16: ECO030 | D16: HU 713/1 x | E16: AS 1523 | F16: MLE 1424 | G16: 0 | H16: OX371D | J16: E60HD110 | K16: PurfluxL330-Fıat73500049-FıaamFA5677ECO | L16: Albea, Doblo Multijet 1.3 | M16: FIAT-ALFA ROMEO-LANCIA | N16: OIL FILTERS | O16: 73500049 | P16: MATCH | Q16: DE427E | R16: ECO030
A17: DE429E ECO042 HU712/7X AS1580 MLE1425 L114 OX418D E107HD166 5650367 55197218 | B17: DE 429 E | C17: ECO042 | D17: HU 712/7 x | E17: AS 1580 | F17: MLE 1425 | G17: L114 | H17: OX418D | J17: E107HD166 | K17: 5650367 | L17: Fiorino 1.3 Multijet(08-->), Linea 1.3JTD | M17: FIAT-ALFA ROMEO-LANCIA | N17: OIL FILTERS | O17: 55197218 | P17: MATCH | Q17: DE429E | R17: ECO042
A18: DS1092 ESO082 W1126-W11261-W11262 SP628 ZP568 OC17-OC133 LF580 H40W 4371581 | B18: DS 1092 | C18: ESO082 | D18: W1126-W11261-W11262 | E18: SP 628 | F18: ZP 568 | H18: OC17-OC133 | I18: LF580 | J18: H40W | L18: FIAT Ducato 2.4D,2.5D | M18: FIAT-ALFA ROMEO-LANCIA | N18: OIL FILTERS | O18: 4371581 | P18: MATCH | Q18: DS1092 | R18: ESO082
A19: DS1207 ESO095 W712/16 SP834 ZP553A OC272 H90W15 46808398 | B19: DS 1207 | C19: ESO095 | D19: W 712/16 | E19: SP 834 | F19: ZP 553A | H19: OC272 | J19: H90W15 | L19: Panda II 1.1,1.2, Punto II, Stilo 1.8 | M19: FIAT-ALFA ROMEO-LANCIA | N19: OIL FILTERS | O19: 46808398 | P19: MATCH | Q19: DS1207 | R19: ESO095
A20: DS1245 ESO121 W79 SP939 ZP3107 OC471 46796687 | B20: DS 1245 | C20: ESO121 | D20: W 79 | E20: SP 939 | F20: ZP 3107 | H20: OC471 | L20: Bravo,Doblo,Punto II,Stilo 1.9 JTD | M20: FIAT-ALFA ROMEO-LANCIA | N20: OIL FILTERS | O20: 46796687 | P20: MATCH | Q20: DS1245 | R20: ESO121
A21: DS1245 ESO123 W79 SP939 ZP3107 H90W28 46796687 | B21: DS 1245 | C21: ESO123 | D21: W 79 | E21: SP 939 | F21: ZP 3107 | J21: H90W28 | L21: Bravo,Doblo,Punto II,Stilo 1.9 JTD | M21: FIAT-ALFA ROMEO-LANCIA | N21: OIL FILTERS | O21: 46796687 | P21: MATCH | Q21: DS1245 | R21: ESO123
A22: DS1221 ESO039 W713/5 SP573 ZP523B 4176610 | B22: DS 1221 | C22: ESO039 | D22: W 713/5 | E22: SP 573 | F22: ZP 523B | L22: Tempra 1.8ie, 2.0ie ,Tipo 1.8ie,2.0ie | M22: FIAT-ALFA ROMEO-LANCIA | N22: OIL FILTERS | O22: 4176610 | P22: MATCH | Q22: DS1221 | R22: ESO039
A23: DS1224 ESO041 W713/16 SP572 ZP553 Z196 OC66 5984044 | B23: DS 1224 | C23: ESO041 | D23: W 713/16 | E23: SP 572 | F23: ZP 553 | G23: Z196 | H23: OC66 | L23: Uno, Tipo, Tempra, Doğan, Şahin,Kartal, Siena,Palio, Marea,Bravo | M23: FIAT-ALFA ROMEO-LANCIA | N23: OIL FILTERS | O23: 5984044 | P23: MATCH | Q23: DS1224 | R23: ESO041
A24: DS1226 ESO158 W713/23 SP571 ZP523C 4212109 | B24: DS 1226 | C24: ESO158 | D24: W 713/23 | E24: SP 571 | F24: ZP 523C | L24: Uno 1.3,1.4, Tipo 1.4,1.6, Tempra 1.4,1.6 | M24: FIAT-ALFA ROMEO-LANCIA | N24: OIL FILTERS | O24: 4212109 | P24: MATCH | Q24: DS1226 | R24: ESO158
A25: DS1229 ESO193 W714/4 SP903 ZP3553 46402457 | B25: DS 1229 | C25: ESO193 | D25: W 714/4 | E25: SP 903 | F25: ZP 3553 | L25: Doblo,Siena,Marea 1.9JTD (01-->) | M25: FIAT-ALFA ROMEO-LANCIA | N25: OIL FILTERS | O25: 46402457 | P25: MATCH | Q25: DS1229 | R25: ESO193
A26: DS1281 ESO064 W920/21 SP407 ZP506 Z257 OC204 4126435 | B26: DS 1281 | C26: ESO064 | D26: W 920/21 | E26: SP 407 | F26: ZP 506 | G26: Z257 | H26: OC204 | L26: Tofaş All Models | M26: FIAT-ALFA ROMEO-LANCIA | N26: OIL FILTERS | O26: 4126435 | P26: MATCH | Q26: DS1281 | R26: ESO064
A27: DS1281 ESO040 W920/21 SP407 ZP506 Z176 OC141 4126435 | B27: DS 1281 | C27: ESO040 | D27: W 920/21 | E27: SP 407 | F27: ZP 506 | G27: Z176 | H27: OC141 | L27: Tofaş All Models | M27: FIAT-ALFA ROMEO-LANCIA | N27: OIL FILTERS | O27: 4126435 | P27: MATCH | Q27: DS1281 | R27: ESO040
A28: DS1319 ESO051B W940/62 SP1445 ZP549B 8093784 | B28: DS 1319 | C28: ESO051B | D28: W 940/62 | E28: SP 1445 | F28: ZP 549B | L28: Ducato 2.3JTD,2.8JTD (02-06) | M28: FIAT-ALFA ROMEO-LANCIA | N28: OIL FILTERS | O28: 8093784 | P28: MATCH | Q28: DS1319 | R28: ESO051B
A29: DE508FE ECF025 PU723X AS3529 MFE1558MB F116 KX208D E83KPD140 77362340 | B29: DE 508 FE | C29: ECF025 | D29: PU 723 x | E29: AS3529 | F29: MFE 1558MB | G29: F116 | H29: KX208D | J29: E83KPD140 | K29: 77362340 | L29: Albea, Doblo Multijet, Ducato (2002-->) (Paper) | M29: FIAT-ALFA ROMEO-LANCIA | N29: FUEL FILTERS | O29: 77362340 | P29: MATCH | Q29: DE508FE | R29: ECF025
A30: DE508FEN ECF025 PU723X AS3529 KFE1460 F116 KX208D E83KPD140 77362340 | B30: DE 508 FEN | C30: ECF025 | D30: PU723X | E30: AS 3529 | F30: KFE 1460 | G30: F116 | H30: KX208D | J30: E83KPD140 | K30: 77362340 | L30: Albea, Doblo Multijet, Ducato (2002-->) (Felt) | M30: FIAT-ALFA ROMEO-LANCIA | N30: FUEL FILTERS | O30: 77362340 | P30: MATCH | Q30: DE508FEN | R30: ECF025
A31: DE552FES ECF061 PU830X AS3555WDK MFE1417MB F101 9401906768 | B31: DE 552 FES | C31: ECF061 | D31: PU 830 x | E31: AS 3555 WDK | F31: MFE 1417MB | G31: F101 | L31: Scudo 2.0 JTD,Ulysse II,Lancia Phedra | M31: FIAT-ALFA ROMEO-LANCIA | N31: FUEL FILTERS | O31: 9401906768 | P31: MATCH | Q31: DE552FES | R31: ECF061
A32: DE531FE ECF007 PU922X AS3522 MFE1363 F691 KX87D E62KPD91 9401906508 | B32: DE 531 FE | C32: ECF007 | D32: PU 922 x | E32: AS 3522 | F32: MFE 1363 | G32: F691 | H32: KX87D | J32: E62KPD91 | L32: Scudo 2.0 JTD 06/00-->(Bosch) | M32: FIAT-ALFA ROMEO-LANCIA | N32: FUEL FILTERS | O32: 9401906508 | P32: MATCH | Q32: DE531FE | R32: ECF007
A33: DE506FE ECF008 PU1021X AS3646 MFE1332 FM646 DÜZELTİLDİ! 9628890680 | B33: DE 506 FE | C33: ECF008 | D33: PU 1021 x | E33: AS 3646 | F33: MFE 1332 | G33: FM646 | H33: DÜZELTİLDİ! | L33: Scudo 1.9D 04/98> | M33: FIAT-ALFA ROMEO-LANCIA | N33: FUEL FILTERS | O33: 9628890680 | P33: MATCH | Q33: DE506FE | R33: ECF008
A34: DS1450F ESF117 WK821 SP641M ZP3034F KC51-KC52 71736114 | B34: DS 1450 F | C34: ESF117 | D34: WK 821 | E34: SP 641 M | F34: ZP 3034F | H34: KC51-KC52 | L34: Bravo,Fiorino, Marea 1.9TD | M34: FIAT-ALFA ROMEO-LANCIA | N34: FUEL FILTERS | O34: 71736114 | P34: MATCH | Q34: DS1450F | R34: ESF117
A35: DS1466F ESF016 WK842/2 SP597M ZP05AF M351A KC17D FF5135 H70WK02 37135706 | B35: DS 1466 F | C35: ESF016 | D35: WK 842/2 | E35: SP 597 M | F35: ZP 05AF | G35: M351A | H35: KC17D | I35: FF5135 | J35: H70WK02 | L35: Ducato 1.9D (81-02), Siena 1.7TD (96-->) | M35: FIAT-ALFA ROMEO-LANCIA | N35: FUEL FILTERS | O35: 37135706 | P35: MATCH | Q35: DS1466F | R35: ESF016
A36: DS1478F ESF112 WK854/6 SP897M ZP3071F M609 KC140 H159WK 46797378 | B36: DS 1478 F | C36: ESF112 | D36: WK 854/6 | E36: SP 897 M | F36: ZP 3071F | G36: M609 | H36: KC140 | J36: H159WK | L36: Yeni Doblo 1.9JTD 01/01-->,Bravo,Ducato,Marea,Palio,Siena,Stilo | M36: FIAT-ALFA ROMEO-LANCIA | N36: FUEL FILTERS | O36: 46797378 | P36: MATCH | Q36: DS1478F | R36: ESF112
A37: DS1531F ESF080 WK853/8 SP698M ZP3041CF M350 KC112 FF5046 H81WK01 9947995 | B37: DS 1531 F | C37: ESF080 | D37: WK 853/8 | E37: SP 698 M | F37: ZP 3041CF | G37: M350 | H37: KC112 | I37: FF5046 | J37: H81WK01 | L37: Brava,Bravo,Marea, Punto II, 1.9 JTD(99-00) | M37: FIAT-ALFA ROMEO-LANCIA | N37: FUEL FILTERS | O37: 9947995 | P37: MATCH | Q37: DS1531F | R37: ESF080
A38: DF4146S EPA004 C2859 HP2153 LX1827 E1020L 46481588 55192012 | B38: DF 4146 S | C38: EPA004 | D38: C 2859 | F38: HP 2153 | H38: LX1827 | J38: E1020L | K38: 46481588 | L38: Punto III, 1.2 8V,1.4 8V (05-->) | M38: FIAT-ALFA ROMEO-LANCIA | N38: AIR FILTERS | O38: 55192012 | P38: MATCH | Q38: DF4146S | R38: EPA004
A39: DP3058 ERA005 C12104 HF5103 HPU4391 LX855 E480L 7721380 46552772 | B39: DP 3058 | C39: ERA005 | D39: C 12104 | E39: HF 5103 | F39: HPU 4391 | H39: LX855 | J39: E480L | K39: 7721380 | L39: Punto II 1.9 JTD 07/03--> | M39: FIAT-ALFA ROMEO-LANCIA | N39: AIR FILTERS | O39: 46552772 | P39: MATCH | Q39: DP3058 | R39: ERA005
A40: DF4021 EPA006 C2341 HF8088 HP2082 LX580 E547L 7701477208 46536382 | B40: DF 4021 | C40: EPA006 | D40: C 2341 | E40: HF 8088 | F40: HP 2082 | H40: LX580 | J40: E547L | K40: 7701477208 | L40: Panda I 1.1,Punto I 1.1,1.2(94-00) | M40: FIAT-ALFA ROMEO-LANCIA | N40: AIR FILTERS | O40: 46536382 | P40: MATCH | Q40: DF4021 | R40: EPA006
...

Sheet DELSA x EKSPER
A1: DELSA | B1: EKSPER | C1: MANN | D1: ASAS | E1: FIL | F1: MISFAT | G1: MAHLE | H1: FLEETGUARD | I1: HENGST | J1: AUTRES | K1: APPLICATION | L1: MARQUE/VEHICULE | M1: TYPE FILTRE | N1: OEM
A2: DA 2003 J | B2: EHA191 | D2: HF 602 | E2: H 871 | H2: AF4100 | K2: VOLVO Penta TD100GG,TWD1211G | L2: VOLVO(Penta,Lorry,Bus) | M2: AIR FILTERS | N2: 823701
A3: DA 2004 J | B3: EHA191 | D3: HF 602 | E3: H 871 | H3: AF4100 | K3: VOLVO Penta TD100GG,TWD1211G (interchangeable set) | L3: VOLVO(Penta,Lorry,Bus) | M3: AIR FILTERS | N3: 823701
A4: DA 2006 J | B4: EHA208 | D4: HF 622 | E4: H 885 | H4: AF25312 | K4: VOLVO Penta TAD1613,1630G,1631G | L4: VOLVO(Penta,Lorry,Bus) | M4: AIR FILTERS | N4: 865152
A5: DA 2009 J | B5: EHA086 | C5: C17127 | E5: H 801 | H5: AH1189 | K5: Thermo-King SB, SMX, SL ;11-5978 (perforated) | L5: OTHER AGRICULTURE AND HEAVY DUTY MACHINES | M5: AIR FILTERS | N5: 11-7400
A6: DA 2010 J | B6: EHA086 | C6: C17127 | E6: H 801 | H6: AH1189 | K6: Thermo-King SB, SMX, SL ;11-5978 (unperforated ) | L6: OTHER AGRICULTURE AND HEAVY DUTY MACHINES | M6: AIR FILTERS | N6: 11-7400
A7: DA 2011 E | B7: EHA101 | C7: C 1140 | D7: HF3204 | E7: HP 2590 | K7: Travego, Tourismo, Setra S400 | L7: MERCEDES COMMERCIAL | M7: AIR FILTERS | N7: 000 989 13 11
A8: DA 2013 E | B8: EHA005 | C8: C 14130 | D8: HF 830 | E8: HP 2606 | G8: LX1566 | I8: E482L | J8: Volvo3979928 | K8: Caddy III SDI,Golf V 1.616V,Jetta II(05=>),Y.Passat 1.6 | L8: VOLKSWAGEN(AUDI,SEAT,SKODA) | M8: AIR FILTERS | N8: 1F0 129 620
A9: DA 2014 E | B9: EHA017 | C9: C 15200 | D9: HF 531 | E9: HP 4592 | G9: LX388 | H9: AF25069 | I9: E295L | J9: MD620563 | K9: T.porter 207-210,307-310,407-410 (71-96)- (Housing) | L9: MERCEDES | M9: AIR FILTERS | N9: 003 094 51 04
A10: DA 2015 E | B10: EHA001 | C10: C 411776 | D10: HF 854 | E10: HP 2627 | G10: LX8141 | H10: AF26165 | I10: E497L | J10: 1F0129620 | K10: Axor I,II serie(04-->) | L10: MERCEDES COMMERCIAL | M10: AIR FILTERS | N10: 004 094 24 04
A11: DA 2016 E | B11: EHA022 | C11: C 16134/1 | D11: HF 801 | E11: HP 2633 | G11: LX1780 | I11: E1010L | J11: 2S1286 | K11: Focus C-max I,II, Focus II .6,1.6TDCi,2.0TDCi | L11: FORD | M11: AIR FILTERS | N11: 7M519601AC
A12: DA 2017 E | B12: EHA159 | C12: C1233 | D12: HF 2834 | J12: FILMAR AF4683 | K12: HATZ Compressor | L12: OTHER AGRICULTURE AND HEAVY DUTY MACHINES | M12: AIR FILTERS | N12: 50426000
A13: DA 2018 E | B13: EHA205 | D13: HF 525 | E13: HP 2503 | H13: AF25438 | K13: MITSUBISHI Canter | L13: MITSUBISHI | M13: AIR FILTERS | N13: ME 017242
A14: DA 2041 K | B14: EHA094 | D14: HF 342 | H14: AF4887KM | K14: M.FERGUSON 255 T. Outer | L14: MASSEY FERGUSON | M14: AIR FILTERS | N14: SMP 77 1579
A15: DA 2042 N | B15: EHA095 | C15: CF751 | D15: HF 343 | E15: HP4616 | H15: AF1966-AF4744 | K15: M.FERGUSON 255 T. Inner | L15: MASSEY FERGUSON | M15: AIR FILTERS | N15: SMP 77 0181
A16: DA 2046 | B16: EHA164 | C16: C 17134 | D16: HF 271 | E16: HP719 | G16: LX196 | H16: AF4137 | I16: E277L | K16: DEUTZ D06,D07D07C,DX3,DX4 Serie (OUTER) | L16: OTHER AGRICULTURE AND HEAVY DUTY MACHINES | M16: AIR FILTERS | N16: 221 1565
A17: DA 2057 | B17: EHA057 | C17: C 25860 | D17: HF 5803 | E17: HP 2691 | G17: LX655 | H17: AF25237 | I17: E251L | K17: DAF 65.180,75.240,85.300 series | L17: DAF | M17: AIR FILTERS | N17: 131453-1
A18: DA 2057 | B18: EHA126 | C18: C 25860 | D18: HF 5803 | E18: HP 2691 | K18: DAF 65.180,75.240,85.300 series | L18: DAF | M18: AIR FILTERS | N18: 131453-1
A19: DA 2065 | B19: EHA129 | C19: C 24393 | D19: HF 516 | E19: HP 732A | G19: LX562 | H19: AF4972 | I19: E219L | K19: IVECO EuroCargo | L19: IVECO | M19: AIR FILTERS | N19: 190 5983
A20: DA 2072 K | B20: EHA089 | C20: C 934 | D20: HF 361 | E20: HP 937K | G20: LX13 | H20: AF1658K | I20: E750L | K20: KUBOTA B1000,4000,5000,6000,7000,8000 | L20: OTHER AGRICULTURE AND HEAVY DUTY MACHINES | M20: AIR FILTERS | N20: 15222 11220
A21: DA 2074 | B21: EHA197 | C21: C 18267 | D21: HF 532 | E21: HP 4537A | H21: AF4856M | K21: M.FERRGUSON 3050-60-65-70-75-80 (Square Cap) | L21: MASSEY FERGUSON | M21: AIR FILTERS | N21: 1 062 501 M91
A22: DA 2075 N | B22: EHA036 | C22: CF 922 | D22: HF 232 | E22: HP 656 | G22: LXS214 | H22: AF4103 | I22: E567LS | J22: 10044213 | K22: M.FERRGUSON 3050-60-65-70-75-80 inner | L22: MASSEY FERGUSON | M22: AIR FILTERS | N22: 1 093 683 M
A23: DA 2076 K | B23: EHA219 | C23: C 16150; C 16223 | D23: HF 515 | E23: HP4685K | H23: AF25324K | K23: M.FERGUSON 375,390,398,399 outer | L23: MASSEY FERGUSON | M23: AIR FILTERS | N23: 3 515 586 M 1
A24: DA 2077 N | B24: EHA141 | C24: CF 961 | D24: HF 485 | E24: HP 656B | K24: M.FERGUSON 375,390,398,399 inner | L24: MASSEY FERGUSON | M24: AIR FILTERS | N24: 3 515 587 M 1
A25: DA 2078 | B25: EHA056 | C25: C 30703 | D25: HF 387 | E25: HP 916A | G25: LX531 | H25: AF25045M-AF25066-AF4630 | I25: E218L | K25: SCANIA Century 13.37(02-->) L113,L94, S113AL (Outer) | L25: SCANIA | M25: AIR FILTERS | N25: 395 773
A26: DA 2092 K | B26: EHA177 | C26: C 21 012 | D26: HF 368 | E26: HP368? | H26: AF25348K | K26: FIAT-AGRI 55-90,580,60-90,680,780 Outer | L26: OTHER AGRICULTURE AND HEAVY DUTY MACHINES | M26: AIR FILTERS | N26: 1903824
A27: DA 2100 | B27: EHA016 | C27: C 331015 | D27: HF 388 | E27: HP 427 | G27: LX441 | H27: AF4842 | I27: E273L | K27: SK serie, 1838,2031,2038 | L27: MERCEDES COMMERCIAL | M27: AIR FILTERS | N27: 003 094 42 04
A28: DA 2102 | B28: EHA103 | C28: C 33920/5 | D28: HF 486 | E28: HP970 | K28: IVECO Trakker 270,310,330,350 (04-->) | L28: IVECO | M28: AIR FILTERS | N28: 299 1793
A29: DA 2103 K | B29: EHA232 | C29: C 14123 | D29: HF 475 | H29: AF25540K | K29: JCB 2CX,2CXL 4x4 (92-->) (Ourter) | L29: J.C.B. | M29: AIR FILTERS | N29: 32/905001
A30: DA 2106 | B30: EHA197 | C30: C 18 267 | D30: HF 532 | E30: HP 4537A | H30: AF4856M | K30: M.FERRGUSON 3050,3060,3065,3070 3075,3080 | L30: MASSEY FERGUSON | M30: AIR FILTERS | N30: 1 062 501 M91
A31: DA 2109 | B31: EHA207 | D31: HF 692 | I31: E742L | K31: VOLVO FL6-serie | L31: VOLVO(Penta,Lorry,Bus) | M31: AIR FILTERS | N31: 3120490
A32: DA 2115 | B32: EHA130 | C32: C 24508 | D32: HF 446 | E32: HP 4014 | G32: LX345 | H32: AF4968 | I32: E214L | K32: IVECO EuroCargo Outer | L32: IVECO | M32: AIR FILTERS | N32: 190 7553
A33: DA 2117 | B33: EHA240 | C33: C 28950 | D33: HF 327 | E33: HP 4017 | H33: AF975M | I33: E739L | K33: CAT 330(6WT1) (90-96) Outer | L33: CATERPILLAR | M33: AIR FILTERS | N33: 7Y 1323
A34: DA 2118 | B34: EHA195 | C34: CF 16219 | D34: HF 328 | E34: HP 4018 | H34: AF976 | K34: CAT 330(6WT1) (90-96) Inner | L34: CATERPILLAR | M34: AIR FILTERS | N34: 7Y 1322
A35: DA 2120 | B35: EHA131 | C35: C22558 | D35: HF 338 | E35: HP 4076 | H35: AF4838 | K35: KOMATSU GD,PC(Exc) serie Outer | L35: KOMATSU | M35: AIR FILTERS | N35: 600 181 6740
A36: DA 2121 | B36: EHA132 | C36: C13111 | D36: HF 354 | E36: HP 4077 | H36: AF4896 | K36: KOMATSU GD,PC(Exc) serie Inner | L36: KOMATSU | M36: AIR FILTERS | N36: 600 181 6730
A37: DA 2126 | B37: EHA033 | C37: C 19457 | D37: HF 296 | E37: HP 4085 | H37: AF4567 | I37: E745L | J37: 894334906 | K37: KOMATSU PC 100-6,120-6,130-6 | L37: KOMATSU | M37: AIR FILTERS | N37: 600 181 6540
A38: DA 2128 N | B38: EHA100 | D38: HF 539 | E38: HP 4092 | H38: AF4654 | K38: M.FERGUSON 255 Turbo Outer | L38: MASSEY FERGUSON | M38: AIR FILTERS | N38: 3310358M1
A39: DA 2129 | B39: EHA037 | C39: C 1699 | D39: HF 441 | E39: HP 4100 | G39: LX1077 | H39: AF25372 | J39: 1930765 | K39: ISUZU Rodeo 2.5L,2.8L Turbo (90-00) | L39: ISUZU | M39: AIR FILTERS | N39: 894334906
A40: DA 2148 | B40: EHA218 | C40: C31009X | E40: HP 4520 | H40: AF4801 | K40: J.DEERE 330LC,370,8760,8770,9600 Outer | L40: JOHN DEERE | M40: AIR FILTERS | N40: AR 95758
...

Sheet DELSA SANS EKSPER
A1: DELSA | B1: MANN | C1: ASAS | D1: FIL | E1: MISFAT | F1: APPLICATION | G1: MARQUE/VEHICULE | H1: TYPE FILTRE | I1: OEM
A2: DA 2001 J | C2: HF 1602 | D2: H 869 | F2: VOLVO Penta TMD100C,TAMD30A,60A,60C | G2: VOLVO(Penta,Lorry,Bus) | H2: AIR FILTERS | I2: 842280
A3: DA 2005 | B3: C 18575 | C3: HF 290 | D3: HP 796 | F3: VOLVO Jenaratör Inner Element | G3: VOLVO(Penta,Lorry,Bus) | H3: AIR FILTERS | I3: 823701
A4: DA 2012 E | B4: C 1250 | D4: HP 2635 | F4: FIAC Compressor | G4: OTHER AGRICULTURE AND HEAVY DUTY MACHINES | H4: AIR FILTERS | I4: 7211450010
A5: DA 2019 E | D5: HP 2508 | F5: MAZDA B2500 single-double cabin pick-up | G5: MAZDA | H5: AIR FILTERS | I5: WL 3113Z40
A6: DA 2020 E | C6: HF 625 | D6: HP 2509 | F6: MITSUBISHI CANTER (INTERCOOL) | G6: MITSUBISHI | H6: AIR FILTERS | I6: ME 017246
A7: DA 2021 E | C7: HF 1420 | F7: TOYOTA Double Cabin (Plastic Capped) | G7: TOYOTA | H7: AIR FILTERS | I7: 17801-54180
A8: DA 2024 D | C8: HF 259 | D8: H 846 | F8: CATERPILLAR 3408,3412,3406 | G8: CATERPILLAR | H8: AIR FILTERS | I8: 4N 0015
A9: DA 2027 D | F9: CAT 120HES,12HNA,16HNA,163H,140H | G9: CATERPILLAR | H9: AIR FILTERS | I9: 9X 4986
A10: DA 2029 EU | B10: C 12133 | D10: HP 2619 | F10: MERCEDES E270 E280 E320 CDi 02--> | G10: MERCEDES | H10: AIR FILTERS | I10: 646 094 00 04
A11: DA 2030 EU | B11: C 12178/1 | D11: HP 2634 | F11: E200 CDI(02-->),S320 CDI(02-05) | G11: MERCEDES | H11: AIR FILTERS | I11: 611 094 02 04
A12: DA 2031 OV | B12: C 1891 | C12: HF 469 | D12: HP 4556 | F12: HYUNDAI H1 Starex 2.4i,Sonata I,II,II 2.0i | G12: HYUNDAI | H12: AIR FILTERS | I12: 28113-32510
A13: DA 2032 KU | B13: C 14 010 | D13: HP 4544K | F13: SAME Tractor Explorer serie (Outer) | G13: OTHER AGRICULTURE AND HEAVY DUTY MACHINES | H13: AIR FILTERS | I13: 242493401
A14: DA 2033 UN | B14: CF 903 | D14: HP 4545 | F14: SAME Tractor Explorer serie (Inner) | G14: OTHER AGRICULTURE AND HEAVY DUTY MACHINES | H14: AIR FILTERS | I14: 242493402
A15: DA 2034 U | B15: C 22 835 | D15: HP 413 | F15: CAT | G15: CATERPILLAR | H15: AIR FILTERS | I15: 7W 7426
A16: DA 2036 U | F16: FORD Cargo 1011,1013,1015,1111(82-96) | G16: FORD COMMERCIAL | H16: AIR FILTERS | I16: 81DB 9601 JB
A17: DA 2038 | C17: HF 417 | D17: HP 461D | F17: MAZDA Titan 3.0,3.5 (83-89) | G17: MAZDA | H17: AIR FILTERS | I17: S 508 23 603
A18: DA 2039 | F18: Minsk Motorcycle | G18: OTHER AUTOMOBILES | H18: CABIN FILTERS
A19: DA 2040 | F19: Jawa, 250 Motorcycle | G19: OTHER AUTOMOBILES | H19: CABIN FILTERS
A20: DA 2043 | F20: KOMATSU Underride Ventilation | G20: KOMATSU | H20: AIR FILTERS
A21: DA 2044 | F21: Liaz tır-627961112411 | G21: OTHER LORRY AND BUSES | H21: CABIN FILTERS | I21: 627961112411
A22: DA 2047 N | B22: CF 711 | C22: HF 671 | F22: DEUTZ D06,D07D07C,DX3,DX4 Serie (INNER) | G22: OTHER AGRICULTURE AND HEAVY DUTY MACHINES | H22: AIR FILTERS | I22: 237 9161
A23: DA 2050 K | C23: HF 595 | F23: SAME 70-80-90 Outer Filter | G23: OTHER AGRICULTURE AND HEAVY DUTY MACHINES | H23: AIR FILTERS | I23: 2.4249.110.1
A24: DA 2051 N | C24: HF 596 | F24: SAME 70-80-90 Inner Filter | G24: OTHER AGRICULTURE AND HEAVY DUTY MACHINES | H24: AIR FILTERS | I24: 2.4249.120.1
A25: DA 2052 | C25: HF 569 | F25: HYUNDAI Galloper 3.0 V6 | G25: HYUNDAI | H25: AIR FILTERS | I25: MD 620610
A26: DA 2054 K | F26: IVECO Lorry (Outer) | G26: IVECO | H26: AIR FILTERS | I26: AZA 344V06J20
A27: DA 2055 | F27: IVECO Lorry (Inner) | G27: IVECO | H27: AIR FILTERS | I27: AZA 345V06J16
A28: DA 2056 | B28: C 13122, C 14130 | C28: HF 451 | D28: HP 470C | F28: HYUNDAI H100 2.5D Panelvan (94-00) | G28: HYUNDAI | H28: AIR FILTERS | I28: 28130-44000
A29: DA 2058 | B29: C 1176 | F29: VOLVO S-serie 840 | G29: VOLVO(Penta,Lorry,Bus) | H29: AIR FILTERS | I29: 735 4867
A30: DA 2059 N | F30: JOHN DEERE 2000,400,500,600,700 (inner) | G30: JOHN DEERE | H30: AIR FILTERS
A31: DA 2061 N | B31: CF 950 | C31: HF 540 | F31: JCB 4x4 Inner | G31: J.C.B. | H31: AIR FILTERS | I31: 32/903202
A32: DA 2062 | B32: CU 1836 | C32: HF 401 | F32: Unimog Serie U1000,U1150,U1200 U1250,U1300L | G32: MERCEDES COMMERCIAL | H32: AIR FILTERS | I32: 000 835 40 47
A33: DA 2063 N | B33: CF 1620 | C33: HF 672 | F33: M.A.N. Lion Clasic G,UE,UEL serie (Inner) | G33: M.A.N. | H33: AIR FILTERS | I33: 81.08204-0073
A34: DA 2064 | F34: Yanmar L70AE,L60AE,L40AE,L48AE | G34: OTHER AGRICULTURE AND HEAVY DUTY MACHINES | H34: AIR FILTERS | I34: 11425012580
A35: DA 2068 | B35: C 1342 | C35: HF 605 | F35: JOHN DEERE 6000,7000 serie | G35: JOHN DEERE | H35: AIR FILTERS | I35: AL78224
A36: DA 2069 | B36: C 19384 | F36: JOHN DEERE 6000,7000 serie | G36: JOHN DEERE | H36: AIR FILTERS | I36: AL78223
A37: DA 2070 N | C37: HF 350 | F37: HYSTER Forklift H,S serie Inner | G37: OTHER AGRICULTURE AND HEAVY DUTY MACHINES | H37: FORKLIFT FILTERS
A38: DA 2071 | F38: CATERPILLAR | G38: CATERPILLAR | H38: AIR FILTERS | I38: 6P 6664
A39: DA 2073 | B39: C 15248 | C39: HF 500 | D39: HP 4567A | F39: Transporter 207-210,307-310,407-410 (71-96) | G39: MERCEDES | H39: AIR FILTERS | I39: 002 094 70 04
A40: DA 2079 N | B40: CF 1610 | C40: HF 644 | F40: SCANIA Century 13.37(02-->) L113,L94, S113AL (Inner) | G40: SCANIA | H40: AIR FILTERS | I40: 395 813
...

Sheet EKSPER SANS DELSA
A1: EKSPER | B1: MANN | C1: MAHLE | D1: MISFAT | E1: FLEETGUARD | F1: HENGST | G1: ASAS | H1: FIL | I1: AUTRES
A2: ECA017C | B2: CUK2336 | H2: HCK7146
A3: ECA018 | B3: ONFİLHF8192 | C3: Iveco 504119162 | I3: ONFİLHF8192
A4: ECA024 | B4: CU27003 | G4: HF6607 | H4: HC7296
A5: ECA030 | B5: CU42001 | G5: HF6605
A6: ECA034 | B6: HIFI SC70014 | C6: IVECO 2995966 | G6: HF6209
A7: ECA038C | B7: A2048300518
A8: ECF012 | E8: FS1293 | G8: AS3565 | I8: Racor2020PM
A9: ECF021 | E9: FS20401 | I9: Racor2040SM-Racor2040TM
A10: ECF029 | B10: PU1033X | C10: KX192D | D10: F170 | F10: E84KPD148 | G10: AS3567 | I10: 7L6127434B
A11: ECF034UR | B11: U6202xKIT | D11: 0 | G11: ASUR3922KIT | H11: MUE1591
A12: ECF036 | B12: PU90021z-PU9002x | C12: KX340D | D12: F151 | F12: E423KP | G12: AS3569 | H12: MFE1607MB
A13: ECF039UR | B13: U6203YKIT | D13: 0 | G13: ASUR3933KIT | H13: MUE1576
A14: ECF041UR | B14: U6204xKIT | D14: 0 | G14: ASUR3924KIT
A15: ECF043 | D15: #N/A | E15: FS36243 | G15: AS3542 | H15: MFE1617
A16: ECF046UR | B16: U587 | D16: 0 | G16: ASUR3968
A17: ECF047 | B17: PU50z | D17: 0 | G17: AS3850 | I17: YETİŞENYPF572
A18: ECF048 | B18: PU850x | C18: KX732D | D18: 0 | E18: FF5627 | G18: AS3527
A19: ECF049 | D19: #N/A | H19: MFE1641MB
A20: ECF051 | D20: #N/A | E20: FF5251 | G20: AS3832 | I20: CAT1R-0766
A21: ECF053 | B21: VOLVO 21746575 | D21: 0 | G21: AS3584
A22: ECF055 AYNI ECF060 | B22: DAF 2277129 | D22: 0
A23: ECF057 | B23: MERCEDES A4730901451 | C23: KX400D | D23: 0 | E23: HIFI SN 70399
A24: ECF058 | B24: FOMOCCO GK219176AA | D24: 0
A25: ECF059 | B25: DAF 1852005 | C25: 1852005 | D25: 0
A26: ECF060 AYNI ECF055 | B26: DAF 1852006 | C26: 1852006 | D26: 0
A27: ECF063 | D27: #N/A | I27: 3608960-3908960-4461492
A28: ECF065 | B28: PU9003Z | D28: F020 | G28: AS3596 | H28: MFE1524MB
A29: ECF066 | C29: Perkins 4451492 / Onfil EF 2382 M/PL | D29: 0 | I29: Perkins 4451492
A30: ECF067 | C30: 23390-0L070 | D30: 0 | I30: 23390-0L070
A31: ECF068 | B31: MAN 51.12503.0069 | D31: 0
A32: ECF069 | D32: #N/A | F32: E440KPD269 | G32: AS3655 | I32: kitli ve kitsiz olarak satılıyor.
A33: ECF069KIT | D33: #N/A | F33: E440KPD269-2 | G33: AS4001
A34: ECF070 | B34: U5001KIT | C34: P956170 | D34: 0 | G34: ASUR3921KIT
A35: ECO005 | B35: HU7271X | C35: OX133D | D35: L586 | F35: E142HD21 | G35: AS1560-AS1570 | H35: ML1354A | I35: Mercedes1041800109
A36: ECO012 | B36: HU12007x | G36: AS2533 | H36: MLE1486
A37: ECO025KIT | B37: HU721XKIT | G37: AS1582KIT
A38: ECO031 | B38: HU931X | C38: OX157D | D38: 0 | E38: LF3819 | F38: E160HD28 | G38: AS1547 | H38: MLE1344B
A39: ECO039 | B39: HU7196x | C39: OX379D | D39: 0 | F39: E27HD125 | G39: AS1519 | H39: MLE1514 | I39: 06D115466
A40: ECO050x | B40: HU816x | C40: OX387D | D40: L185 | G40: AS2503 | H40: MLE1521V
...

Sheet LISEZMOI
A1: CORRESPONDANCE CROISEE DELSA x EKSPER — Octobre 2026
A4: COMMENT CHERCHER
A5: 1. Feuille RECHERCHE : tapez la reference dans la grande cellule jaune, puis Entree. Les 10 premiers resultats s affichent avec le couple DELSA / EKSPER et toutes les autres marques. La casse et les espaces n ont aucune importance (HU722X = hu 722 x). Marche dans l application Excel, PC ou telephone.
A6: 2. Sans Excel (visionneuse) : feuille TOUTES LES REFERENCES + Ctrl+F — meme resultat, chaque ligne = une reference de n importe quelle marque avec ses equivalents DELSA et EKSPER.
A7: 3. Vous pouvez aussi trier / filtrer chaque colonne avec les fleches d en-tete de chaque feuille.
A10: FEUILLES
A11: RECHERCHE : feuille interactive — tapez une reference, les resultats s affichent.
A12: TOUTES LES REFERENCES : moteur manuel — 1 ligne par reference de chaque marque, colonne B = reference colle sans espaces.
A13: DELSA x EKSPER : les 1055 correspondances etablies cote a cote.
A14: DELSA SANS EKSPER : 1755 references DELSA sans equivalent EKSPER.
A15: EKSPER SANS DELSA : 459 references EKSPER sans equivalent DELSA.
A17: METHODE
A18: Correspondances etablies via les marques communes aux deux catalogues : MANN, ASAS, FIL, MISFAT (references normalisees : majuscules, espaces ignores).
